Workbook
Name Die_Type: Data!$E$2:$E$11
Name Password: Data!$G$1
Name Supplier: Table3[Supplier Name]

Sheet Summary
A3: Plant | B3: STATUS | C3: Supplier | D3: DIE NO | E3: Count of Order No | J3: GEX-1 Dies Budgeted Vs Actual -2025
A4: GEX 1 | B4: AWAITING FOR DESIGN | E4: 5 | J4: Type | K4: JAN | L4: FEB | M4: MAR | N4: APR | O4: MAY | P4: JUN | Q4: JUL | R4: AUG | S4: SEP | T4: OCT | U4: NOV | V4: DEC | W4: YTD | X4: Deviation YTD
B5: PENDING FOR DESIGN APPROVAL | E5: 7 | J5: BACK UP DIES | K5: 48.095349 | L5: 50.67953 | M5: 50.612308 | N5: 45.923212 | O5: 49.518926 | P5: 49.136309 | Q5: 50.927211 | R5: 46.089044 | S5: 50.552392 | T5: 49.390328 | U5: 50.108052 | V5: 48.168525 | W5: =SUM(K5:Q5) -> 344.89285 | X5: =W5-W6 -> -59.107154
B6: PENDING FOR ORDERING | E6: 9 | J6: ACTUAL | K6: =COUNTIFS(tbl_die_ordering[Plant],"GEX 1",tbl_die_ordering[month],Summary!K4,tbl_die_ordering[TYPE],"B") -> 60 | L6: =COUNTIFS(tbl_die_ordering[Plant],"GEX 1",tbl_die_ordering[month],Summary!L4,tbl_die_ordering[TYPE],"B") -> 66 | M6: =COUNTIFS(tbl_die_ordering[Plant],"GEX 1",tbl_die_ordering[month],Summary!M4,tbl_die_ordering[TYPE],"B") -> 47 | N6: =COUNTIFS(tbl_die_ordering[Plant],"GEX 1",tbl_die_ordering[month],Summary!N4,tbl_die_ordering[TYPE],"B") -> 54 | O6: =COUNTIFS(tbl_die_ordering[Plant],"GEX 1",tbl_die_ordering[month],Summary!O4,tbl_die_ordering[TYPE],"B") -> 52 | P6: =COUNTIFS(tbl_die_ordering[Plant],"GEX 1",tbl_die_ordering[month],Summary!P4,tbl_die_ordering[TYPE],"B") -> 49 | Q6: =COUNTIFS(tbl_die_ordering[Plant],"GEX 1",tbl_die_ordering[month],Summary!Q4,tbl_die_ordering[TYPE],"B") -> 76 | R6: =COUNTIFS(tbl_die_ordering[Plant],"GEX 1",tbl_die_ordering[month],Summary!R4,tbl_die_ordering[TYPE],"B") -> 60 | ... V6: =COUNTIFS(tbl_die_ordering[Plant],"GEX 1",tbl_die_ordering[month],Summary!V4,tbl_die_ordering[TYPE],"B") -> 19 | W6: =SUM(K6:Q6) -> 404
B7: UNDER SIMULATION | E7: 13 | J7: NEW DIES | K7: 33.304248 | L7: 35.093698 | M7: 35.047149 | N7: 31.800124 | O7: 34.290022 | P7: 34.025074 | Q7: 35.265208 | R7: 35.265208 | S7: 35.005659 | T7: 34.200973 | U7: 34.69797 | V7: 33.354919 | W7: =SUM(K7:Q7) -> 238.82552 | X7: =W7-W8 -> -104.17448 | AA7: =Q6+Q8 -> 164
A8: GEX 2 | B8: HOLD | E8: 1 | J8: ACTUAL | K8: =COUNTIFS(tbl_die_ordering[Plant],"GEX 1",tbl_die_ordering[month],Summary!K4,tbl_die_ordering[TYPE],"N") -> 63 | L8: =COUNTIFS(tbl_die_ordering[Plant],"GEX 1",tbl_die_ordering[month],Summary!L4,tbl_die_ordering[TYPE],"N") -> 17 | M8: =COUNTIFS(tbl_die_ordering[Plant],"GEX 1",tbl_die_ordering[month],Summary!M4,tbl_die_ordering[TYPE],"N") -> 47 | N8: =COUNTIFS(tbl_die_ordering[Plant],"GEX 1",tbl_die_ordering[month],Summary!N4,tbl_die_ordering[TYPE],"N") -> 70 | O8: =COUNTIFS(tbl_die_ordering[Plant],"GEX 1",tbl_die_ordering[month],Summary!O4,tbl_die_ordering[TYPE],"N") -> 32 | P8: =COUNTIFS(tbl_die_ordering[Plant],"GEX 1",tbl_die_ordering[month],Summary!P4,tbl_die_ordering[TYPE],"N") -> 26 | Q8: =COUNTIFS(tbl_die_ordering[Plant],"GEX 1",tbl_die_ordering[month],Summary!Q4,tbl_die_ordering[TYPE],"N") -> 88 | R8: =COUNTIFS(tbl_die_ordering[Plant],"GEX 1",tbl_die_ordering[month],Summary!R4,tbl_die_ordering[TYPE],"N") -> 27 | S8: =COUNTIFS(tbl_die_ordering[Plant],"GEX 1",tbl_die_ordering[month],Summary!S4,tbl_die_ordering[TYPE],"N") -> 11 | T8: =COUNTIFS(tbl_die_ordering[Plant],"GEX 1",tbl_die_ordering[month],Summary!S4,tbl_die_ordering[TYPE],"N") -> 11 | U8: =COUNTIFS(tbl_die_ordering[Plant],"GEX 1",tbl_die_ordering[month],Summary!U4,tbl_die_ordering[TYPE],"N") -> 33 | V8: =COUNTIFS(tbl_die_ordering[Plant],"GEX 1",tbl_die_ordering[month],Summary!V4,tbl_die_ordering[TYPE],"N") -> 2 | W8: =SUM(K8:Q8) -> 343
B9: PENDING FOR DESIGN APPROVAL | E9: 3
B10: PENDING FOR ORACLE ENTRY | E10: 5 | J10: GEX-2 Dies Budgeted Vs Actual
B11: PENDING FOR ORDERING | E11: 9 | J11: Type | K11: JAN | L11: FEB | M11: MAR | N11: APR | O11: MAY | P11: JUN | Q11: JUL | R11: AUG | S11: SEP | T11: OCT | U11: NOV | V11: DEC | W11: YTD | X11: Deviation YTD
B12: UNDER SIMULATION | E12: 4 | J12: BACK UP DIES | K12: 25 | L12: 25 | M12: 25 | N12: 23 | O12: 24 | P12: 25 | Q12: 25 | R12: 23 | S12: 25 | T12: 23 | U12: 23 | V12: 24 | W12: =SUM(K12:V12) -> 290 | X12: =W12-W13 -> -31
A13: Grand Total | E13: 56 | J13: ACTUAL | K13: =COUNTIFS(tbl_die_ordering[Plant],"GEX 2",tbl_die_ordering[month],Summary!K4,tbl_die_ordering[TYPE],"B") -> 25 | L13: =COUNTIFS(tbl_die_ordering[Plant],"GEX 2",tbl_die_ordering[month],Summary!L4,tbl_die_ordering[TYPE],"B") -> 23 | M13: =COUNTIFS(tbl_die_ordering[Plant],"GEX 2",tbl_die_ordering[month],Summary!M4,tbl_die_ordering[TYPE],"B") -> 28 | N13: =COUNTIFS(tbl_die_ordering[Plant],"GEX 2",tbl_die_ordering[month],Summary!N4,tbl_die_ordering[TYPE],"B") -> 23 | O13: =COUNTIFS(tbl_die_ordering[Plant],"GEX 2",tbl_die_ordering[month],Summary!O4,tbl_die_ordering[TYPE],"B") -> 23 | P13: =COUNTIFS(tbl_die_ordering[Plant],"GEX 2",tbl_die_ordering[month],Summary!P4,tbl_die_ordering[TYPE],"B") -> 25 | Q13: =COUNTIFS(tbl_die_ordering[Plant],"GEX 2",tbl_die_ordering[month],Summary!Q4,tbl_die_ordering[TYPE],"B") -> 27 | R13: =COUNTIFS(tbl_die_ordering[Plant],"GEX 2",tbl_die_ordering[month],Summary!R4,tbl_die_ordering[TYPE],"B") -> 29 | ... V13: =COUNTIFS(tbl_die_ordering[Plant],"GEX 2",tbl_die_ordering[month],Summary!V4,tbl_die_ordering[TYPE],"B") -> 10 | W13: =SUM(K13:V13) -> 321
J14: NEW DIES | K14: 12 | L14: 12 | M14: 12 | N14: 11 | O14: 11 | P14: 12 | Q14: 12 | R14: 11 | S14: 12 | T14: 11 | U14: 11 | V14: 12 | W14: =SUM(K14:V14) -> 139 | X14: =W14-W15 -> -2
J15: ACTUAL | K15: =COUNTIFS(tbl_die_ordering[Plant],"GEX 2",tbl_die_ordering[month],Summary!K4,tbl_die_ordering[TYPE],"N") -> 52 | L15: =COUNTIFS(tbl_die_ordering[Plant],"GEX 2",tbl_die_ordering[month],Summary!L4,tbl_die_ordering[TYPE],"N") -> 5 | M15: =COUNTIFS(tbl_die_ordering[Plant],"GEX 2",tbl_die_ordering[month],Summary!M4,tbl_die_ordering[TYPE],"N") -> 7 | N15: =COUNTIFS(tbl_die_ordering[Plant],"GEX 2",tbl_die_ordering[month],Summary!N4,tbl_die_ordering[TYPE],"N") -> 10 | O15: =COUNTIFS(tbl_die_ordering[Plant],"GEX 2",tbl_die_ordering[month],Summary!O4,tbl_die_ordering[TYPE],"N") -> 5 | P15: =COUNTIFS(tbl_die_ordering[Plant],"GEX 2",tbl_die_ordering[month],Summary!P4,tbl_die_ordering[TYPE],"N") -> 6 | Q15: =COUNTIFS(tbl_die_ordering[Plant],"GEX 2",tbl_die_ordering[month],Summary!Q4,tbl_die_ordering[TYPE],"N") -> 22 | R15: =COUNTIFS(tbl_die_ordering[Plant],"GEX 2",tbl_die_ordering[month],Summary!R4,tbl_die_ordering[TYPE],"N") -> 8 | ... V15: =COUNTIFS(tbl_die_ordering[Plant],"GEX 2",tbl_die_ordering[month],Summary!V4,tbl_die_ordering[TYPE],"N") -> 5 | W15: =SUM(K15:V15) -> 141
J18: Type | K18: JAN | L18: FEB | M18: MAR | N18: APR | O18: MAY | P18: JUN | Q18: JUL | R18: AUG | S18: SEP | T18: OCT | U18: NOV | V18: DEC | W18: YTD
J19: BACK UP DIES | K19: =K5+K12 -> 73.095349 | L19: =L5+L12 -> 75.67953 | M19: =M5+M12 -> 75.612308 | N19: =N5+N12 -> 68.923212 | O19: =O5+O12 -> 73.518926 | P19: =P5+P12 -> 74.136309 | Q19: =Q5+Q12 -> 75.927211 | R19: =R5+R12 -> 69.089044 | ... V19: =V5+V12 -> 72.168525 | W19: =SUM(K19:V19) -> 879.20119
J20: ACTUAL | K20: =K6+K13 -> 85 | L20: =L6+L13 -> 89 | M20: =M6+M13 -> 75 | N20: =N6+N13 -> 77 | O20: =O6+O13 -> 75 | P20: =P6+P13 -> 74 | Q20: =Q6+Q13 -> 103 | R20: =R6+R13 -> 89 | ... V20: =V6+V13 -> 29 | W20: =SUM(K20:V20) -> 1017 | AA20: =Q20+Q22 -> 213
J21: NEW DIES | K21: =K7+K14 -> 45.304248 | L21: =L7+L14 -> 47.093698 | M21: =M7+M14 -> 47.047149 | N21: =N7+N14 -> 42.800124 | O21: =O7+O14 -> 45.290022 | P21: =P7+P14 -> 46.025074 | Q21: =Q7+Q14 -> 47.265208 | R21: =R7+R14 -> 46.265208 | ... V21: =V7+V14 -> 45.354919 | W21: =SUM(K21:V21) -> 550.35025
J22: ACTUAL | K22: =K8+K15 -> 115 | L22: =L8+L15 -> 22 | M22: =M8+M15 -> 54 | N22: =N8+N15 -> 80 | O22: =O8+O15 -> 37 | P22: =P8+P15 -> 32 | Q22: =Q8+Q15 -> 110 | R22: =R8+R15 -> 35 | ... V22: =V8+V15 -> 7 | W22: =SUM(K22:V22) -> 568
A27: Status | B27: Die no | C27: Quality Issue
A28: Hold
A29: OPEN | B29: 014861-3502 | C29: Mandrel deflection and Rib crack
A30: OPEN | B30: 28117-426 | C30: not good shape flow defect. Requested for full set foc die
A31: OPEN | B31: 29826-203 | C31: unbalance flow. Foc Die (full set) requested
A32: OPEN | B32: 30143-401 | C32: Profile shape and dimension not ok. Quality desicrepancy raised for FOC Die Set. Foc die received on 12/04/2025. again QD is reopen due to Diesize Issue. QD sent again on 19/05/2025.
A33: OPEN | B33: 90324-409 | C33: even after 3 trials, shape is not able to achieve, involving supplier for correction
A34: OPEN | B34: Ins-23396 | C34: The QD was sent to Gulfex Purchase on 19/05/2025. Upon inspection, no lifting hole was found on the insert. Therefore, we sent it to a local supplier to have the lifting hole made. The cost for this modification is to be borne by the supplier, Ekstek.
A35: Rejected | B35: 29826-204 | C35: mandrel deflected Foc Mandrel Requested
A36: Grand Total

Sheet Sheet1
A1: Months (Die Requested Date) | B1: Oct
A2: Days (Die Requested Date) | B2: (All)
A3: Die Requested Date | B3: (All)
A5: Row Labels | B5: Count of Die Size
A6: Al saho | B6: 3
A7: Continual Facade | B7: 1
A8: Emirates Global | B8: 1
A9: Hueck | B9: 1
A10: Redcom Contruction | B10: 1
A11: Schuco | B11: 1
A12: Sobha construction | B12: 4
A13: Grand Total | B13: 12

Sheet Sheet3
A1: Plant | B1: Order No | C1: DIE NO | D1: TYPE | E1: Die Size | F1: Die Requested Date | G1: Ordered date | H1: Type of shipment | I1: Mandrels per Cavity | J1: Total Mandrels | K1: Design Received Date | L1: Design Approved Date | M1: Sim | N1: Delay | O1: PR Entry | P1: Oracle Entry | Q1: PR Forwarded date | R1: PR No.: | S1: Supplier | T1: Design saved to EMS FOLDER | U1: Customer of new profile | V1: Remarks | W1: STATUS
A2: GEX 1 | C2: 30392-602 | D2: B | E2: 450X250 | F2: 45971 | H2: AIR | I2: 7 | J2: 7 | S2: WEFA | W2: PENDING FOR ORDERING
A3: GEX 2 | C3: 005279-3507 | D3: B | E3: 355X200 | F3: 45979 | H3: LAND | I3: 1 | J3: 3 | S3: PHME | W3: PENDING FOR ORDERING
A4: GEX 2 | C4: 027911-3501 | D4: B | E4: 450X260 | F4: 45979 | H4: LAND | I4: 0 | J4: 0 | K4: 45981 | L4: 45982 | O4: 45983 | Q4: 45983 | R4: 212501595 | S4: PHME | T4: 45983 | W4: PENDING FOR ORDERING
A5: GEX 1 | C5: 07098-607 | D5: B | E5: 320X160 | F5: 45979 | H5: LAND | I5: 0 | J5: 0 | K5: 45981 | S5: PDTMC | W5: PENDING FOR ORDERING
A6: GEX 1 | C6: 11069-408 | D6: B | E6: 280X160 | F6: 45979 | H6: LAND | I6: 0 | J6: 0 | K6: 45982 | L6: 45982 | O6: 45983 | P6: 45979 | Q6: 45983 | R6: 112505137 | S6: PDTMC | T6: 45983 | W6: PENDING FOR ORDERING
A7: GEX 1 | C7: 28546-601 | D7: B | E7: 320X160 | F7: 45979 | H7: AIR | I7: 1 | J7: 1 | K7: 45982 | S7: JIANGSU | V7: Not for anodizing order | W7: PENDING FOR ORDERING
A8: GEX 1 | C8: 30379-501 | D8: B | E8: 280X160 | F8: 45979 | H8: AIR | I8: 7 | J8: 7 | S8: WEFA | W8: PENDING FOR ORDERING
A9: GEX 1 | C9: 07098-608 | D9: B | E9: 320X160 | F9: 45980 | H9: LAND | I9: 0 | J9: 0 | K9: 45981 | L9: 45982 | O9: 45983 | Q9: 45983 | R9: 112505137 | S9: PHME | T9: 45983 | W9: PENDING FOR ORDERING
A10: GEX 2 | C10: 007108-2503 | D10: B | E10: 220X130 | F10: 45980 | H10: LAND | I10: 0 | J10: 0 | S10: PDTMC | W10: PENDING FOR ORDERING
A11: GEX 1 | C11: 11388-218 | D11: B | E11: 280X160 | F11: 45980 | H11: AIR | I11: 0 | J11: 0 | S11: JIANGSU | W11: PENDING FOR ORDERING
A12: GEX 1 | C12: 12098-215 | D12: B | E12: 280X160 | F12: 45980 | H12: LAND | I12: 1 | J12: 2 | K12: 45982 | S12: PHME | W12: PENDING FOR ORDERING
A13: GEX 2 | C13: 012144-3501 | D13: B | E13: 320X200 | F13: 45980 | H13: LAND | I13: 1 | J13: 2 | K13: 45985 | S13: PDTMC | W13: PENDING FOR ORDERING
A14: GEX 1 | C14: 12725-503 | D14: B | E14: 280X160 | F14: 45980 | H14: LAND | I14: 1 | J14: 2 | S14: PHME | W14: PENDING FOR ORDERING
A15: GEX 2 | C15: 013794-3511 | D15: B | E15: 355X200 | F15: 45980 | H15: AIR | I15: 1 | J15: 2 | S15: JIANGSU | W15: PENDING FOR ORDERING
A16: GEX 1 | C16: 23555-404 | D16: B | E16: 250X160 | F16: 45980 | H16: AIR | I16: 0 | J16: 0 | S16: JIANGSU | W16: PENDING FOR ORDERING
A17: GEX 1 | C17: 27349-502 | D17: B | E17: 250X160 | F17: 45980 | H17: LAND | I17: 0 | J17: 0 | K17: 45981 | L17: 45982 | O17: 45983 | Q17: 45983 | R17: 112505137 | S17: PHME | T17: 45983 | W17: PENDING FOR ORDERING
A18: GEX 2 | C18: 029117-3502 | D18: B | E18: 400X260 | F18: 45980 | H18: LAND | I18: 1 | J18: 3 | K18: 45982 | L18: 45982 | O18: 45983 | Q18: 45983 | R18: 212501595 | S18: PHME | T18: 45983 | W18: PENDING FOR ORDERING
A19: GEX 2 | C19: 029118-2513 | D19: B | E19: 320X160 | F19: 45980 | H19: LAND | I19: 1 | J19: 2 | K19: 45982 | L19: 45982 | O19: 45983 | Q19: 45983 | R19: 212501595 | S19: PHME | T19: 45983 | W19: PENDING FOR ORDERING
A20: GEX 2 | C20: 029118-2501 | D20: B | E20: 320X160 | F20: 45980 | H20: LAND | I20: 1 | J20: 2 | K20: 45982 | L20: 45982 | O20: 45983 | Q20: 45983 | R20: 212501595 | S20: PHME | T20: 45983 | W20: PENDING FOR ORDERING
A21: GEX 2 | C21: 029663-3502 | D21: B | E21: 355X200 | F21: 45980 | H21: LAND | I21: 1 | J21: 2 | S21: PDTMC | W21: PENDING FOR ORDERING
A22: GEX 1 | C22: 29663-211 | D22: B | E22: 355X200 | F22: 45980 | H22: LAND | I22: 1 | J22: 2 | K22: 45983 | S22: PDTMC | W22: PENDING FOR ORDERING
A23: GEX 1 | C23: 30477-602 | D23: B | E23: 550X250 | F23: 45980 | H23: AIR | I23: 5 | J23: 5 | S23: ALMAX | W23: PENDING FOR ORDERING
A24: GEX 2 | C24: 051111-3507 | D24: B | E24: 450X260 | F24: 45980 | H24: LAND | I24: 3 | J24: 3 | K24: 45982 | L24: 45982 | O24: 45983 | Q24: 45983 | R24: 212501595 | S24: PHME | T24: 45983 | W24: PENDING FOR ORDERING
A25: GEX 2 | C25: 120627-2504 | D25: B | E25: 250X140 | F25: 45980 | H25: LAND | I25: 1 | J25: 2 | K25: 45982 | L25: 45982 | O25: 45983 | Q25: 45983 | R25: 212501595 | S25: PHME | T25: 45983 | W25: PENDING FOR ORDERING
A26: GEX 2 | C26: 120507-2503 | D26: B | E26: 280X165 | F26: 45980 | H26: AIR | I26: 3 | J26: 3 | S26: ALMAX | W26: PENDING FOR ORDERING
A27: GEX 1 | C27: 05188-510 | D27: B | E27: 280X160 | F27: 45983 | H27: LAND | I27: 1 | J27: 2 | S27: PDTMC | W27: PENDING FOR ORDERING
A28: GEX 2 | C28: 010745-2501 | D28: B | E28: 280X160 | F28: 45983 | H28: LAND | I28: 0 | J28: 0 | S28: PDTMC | W28: PENDING FOR ORDERING
A29: GEX 1 | C29: 13212-236 | D29: B | E29: 280X160 | F29: 45983 | H29: AIR | I29: 1 | J29: 2 | S29: EKSTEK | W29: PENDING FOR ORDERING
A30: GEX 1 | C30: 13212-409 | D30: B | E30: 220X160 | F30: 45983 | H30: LAND | I30: 1 | J30: 1 | S30: PDTMC | W30: PENDING FOR ORDERING
A31: GEX 1 | C31: 29596-502 | D31: B | E31: 250X160 | F31: 45983 | H31: LAND | I31: 1 | J31: 2 | S31: PDTMC | W31: PENDING FOR ORDERING
A32: GEX 1 | C32: 29897-201 | D32: B | E32: 355X200 | F32: 45983 | H32: LAND | I32: 1 | J32: 2 | S32: PHME | W32: PENDING FOR ORDERING
A33: GEX 1 | C33: 29897-507 | D33: B | E33: 280X160 | F33: 45983 | H33: LAND | I33: 1 | J33: 1 | S33: PDTMC | W33: PENDING FOR ORDERING
A34: GEX 1 | C34: 120661-607 | D34: B | E34: 450X250 | F34: 45983 | H34: LAND | I34: 3 | J34: 3 | S34: PHME | W34: PENDING FOR ORDERING
A35: GEX 1 | C35: 297285-502 | D35: B | E35: 280X160 | F35: 45985 | H35: LAND | I35: 1 | J35: 1 | S35: PHME | W35: PENDING FOR ORDERING
A36: GEX 1 | C36: 29826-501 | D36: B | E36: 320X160 | F36: 45985 | H36: LAND | I36: 4 | J36: 4 | S36: PDTMC | W36: PENDING FOR ORDERING

Sheet Die Ordering
A2: Plant | B2: Order No | C2: DIE NO | D2: TYPE | E2: Die Size | F2: Die Requested Date | G2: Ordered date | H2: Type of shipment | I2: Mandrels per Cavity | J2: Total Mandrels | K2: Design Received Date | L2: Design Approved Date | M2: Sim | N2: Delay | O2: PR Entry | P2: Oracle Entry | Q2: PR Forwarded date | R2: PR No.: | S2: Supplier | T2: Design saved to EMS FOLDER | U2: Customer of new profile | V2: Remarks | W2: STATUS | X2: OVERALL DELAY | Y2: Design Enhancement | Z2: QD Status | AA2: Finish | AB2: PO | AC2: ETA | AD2: Die received | AE2: Design enhancements | AF2: month | AG2: clm_spoort | AH2: Die size changes | AI2: design changes | AJ2: Column1
A3: GEX 1 | B3: =_xlfn.XLOOKUP(_xlfn.TEXTJOIN("_",TRUE,tbl_die_ordering[[#This Row],[Supplier]],tbl_die_ordering[[#This Row],[DIE NO]]),[1]Tracker!$AQ:$AQ,[1]Tracker!$W:$W,"") -> 7613-25 | C3: INS-25033 | D3: T | E3: 300X100 | F3: 45660 | G3: =_xlfn.XLOOKUP(_xlfn.TEXTJOIN("_",TRUE,tbl_die_ordering[[#This Row],[Supplier]],tbl_die_ordering[[#This Row],[DIE NO]]),[1]Tracker!$AQ:$AQ,[1]Tracker!$V:$V,"") -> 45660 | H3: LAND | I3: 0 | J3: 0 | K3: 45660 | L3: 45660 | N3: =IFERROR(IF(tbl_die_ordering[[#This Row],[Design Approved Date]]<>"",L3-K3,""),"") -> 0 | O3: 45661 | P3: 45661 | Q3: 45661 | R3: 112500030 | S3: PDTMC | T3: 45661 | W3: =_xlfn.LET( _xlpm.dieNo, tbl_die_ordering[[#This Row],[DIE NO]], _xlpm.orderNo, tbl_die_ordering[[#This Row],[Order No]], _xlpm.type, tbl_die_ordering[[#This Row],[TYPE]], _xlpm.designReceived, tbl_die_ordering[[#This Row],[Design Received Date]], _xlpm.designApproved, tbl_die_ordering[[#This Row],[Design Approved Date]], _xlpm.sim, tbl_die_ordering[[#This Row],[Sim]], _xlpm.prEntry, tbl_die_ordering[[#This Row],[PR Entry]], _xlpm.oracleEntry, tbl_die_ordering[[#This Row],[Oracle Entry]], _xlpm.ems, tbl_die_ordering[[#This Row],[Design saved to EMS FOLDER]], IF(_xlpm.dieNo = "", "", IF(_xlpm.orderNo = "", "PENDING FOR ORDERING", IF(_xlpm.type = "C", "CANCELLED", IF(_xlpm.type = "H", "HOLD", IF(_xlpm.designReceived = "", "AWAITING FOR DESIGN", IF(_xlpm.designApproved = "", IF(_xlpm.sim = "YES", "UNDER SIMULATION", "PENDING FOR DESIGN APPROVAL"), IF(_xlpm.prEntry = "", "PENDING FOR PR", IF(_xlpm.oracleEntry = "", "PENDING FOR ORACLE ENTRY", IF(_xlpm.ems = "", "PENDING FOR DESIGN TO EMS", "DONE"))))))))) ) -> DONE | X3: =IF(AND(tbl_die_ordering[[#This Row],[TYPE]]<>"C",tbl_die_ordering[[#This Row],[Design Approved Date]]<>""),tbl_die_ordering[[#This Row],[Design Approved Date]]-tbl_die_ordering[[#This Row],[Die Requested Date]],0) -> 0 | AB3: =_xlfn.XLOOKUP(_xlfn.TEXTJOIN("_",TRUE,tbl_die_ordering[[#This Row],[Supplier]],tbl_die_ordering[[#This Row],[DIE NO]]),[1]Tracker!$AQ:$AQ,[1]Tracker!$Y:$Y,"") -> 142500270 | AC3: =_xlfn.XLOOKUP(_xlfn.TEXTJOIN("_",TRUE,tbl_die_ordering[[#This Row],[Supplier]],tbl_die_ordering[[#This Row],[DIE NO]]),[1]Tracker!$AQ:$AQ,[1]Tracker!$AC:$AC,"") -> 45669 | AF3: =TEXT(tbl_die_ordering[[#This Row],[Die Requested Date]],"mmm") -> Jan | AG3: =_xlfn.TEXTJOIN("_",TRUE,tbl_die_ordering[[#This Row],[Supplier]],tbl_die_ordering[[#This Row],[DIE NO]]) -> PDTMC_INS-25033
A4: GEX 1 | B4: =_xlfn.XLOOKUP(_xlfn.TEXTJOIN("_",TRUE,tbl_die_ordering[[#This Row],[Supplier]],tbl_die_ordering[[#This Row],[DIE NO]]),[1]Tracker!$AQ:$AQ,[1]Tracker!$W:$W,"") -> 7610-25 | C4: 01001-402 | D4: B | E4: 250X160 | F4: 45660 | G4: =_xlfn.XLOOKUP(_xlfn.TEXTJOIN("_",TRUE,tbl_die_ordering[[#This Row],[Supplier]],tbl_die_ordering[[#This Row],[DIE NO]]),[1]Tracker!$AQ:$AQ,[1]Tracker!$V:$V,"") -> 45660 | H4: AIR | I4: 0 | J4: 0 | K4: 45660 | L4: 45661 | N4: =IFERROR(IF(tbl_die_ordering[[#This Row],[Design Approved Date]]<>"",L4-K4,""),"") -> 1 | O4: 45665 | P4: 45666 | Q4: 45665 | R4: 112500093 | S4: EKSTEK | T4: 45665 | W4: =_xlfn.LET( _xlpm.dieNo, tbl_die_ordering[[#This Row],[DIE NO]], _xlpm.orderNo, tbl_die_ordering[[#This Row],[Order No]], _xlpm.type, tbl_die_ordering[[#This Row],[TYPE]], _xlpm.designReceived, tbl_die_ordering[[#This Row],[Design Received Date]], _xlpm.designApproved, tbl_die_ordering[[#This Row],[Design Approved Date]], _xlpm.sim, tbl_die_ordering[[#This Row],[Sim]], _xlpm.prEntry, tbl_die_ordering[[#This Row],[PR Entry]], _xlpm.oracleEntry, tbl_die_ordering[[#This Row],[Oracle Entry]], _xlpm.ems, tbl_die_ordering[[#This Row],[Design saved to EMS FOLDER]], IF(_xlpm.dieNo = "", "", IF(_xlpm.orderNo = "", "PENDING FOR ORDERING", IF(_xlpm.type = "C", "CANCELLED", IF(_xlpm.type = "H", "HOLD", IF(_xlpm.designReceived = "", "AWAITING FOR DESIGN", IF(_xlpm.designApproved = "", IF(_xlpm.sim = "YES", "UNDER SIMULATION", "PENDING FOR DESIGN APPROVAL"), IF(_xlpm.prEntry = "", "PENDING FOR PR", IF(_xlpm.oracleEntry = "", "PENDING FOR ORACLE ENTRY", IF(_xlpm.ems = "", "PENDING FOR DESIGN TO EMS", "DONE"))))))))) ) -> DONE | X4: =IF(AND(tbl_die_ordering[[#This Row],[TYPE]]<>"C",tbl_die_ordering[[#This Row],[Design Approved Date]]<>""),tbl_die_ordering[[#This Row],[Design Approved Date]]-tbl_die_ordering[[#This Row],[Die Requested Date]],0) -> 1 | AB4: =_xlfn.XLOOKUP(_xlfn.TEXTJOIN("_",TRUE,tbl_die_ordering[[#This Row],[Supplier]],tbl_die_ordering[[#This Row],[DIE NO]]),[1]Tracker!$AQ:$AQ,[1]Tracker!$Y:$Y,"") -> 142500488 | AC4: =_xlfn.XLOOKUP(_xlfn.TEXTJOIN("_",TRUE,tbl_die_ordering[[#This Row],[Supplier]],tbl_die_ordering[[#This Row],[DIE NO]]),[1]Tracker!$AQ:$AQ,[1]Tracker!$AC:$AC,"") -> 45681 | AF4: =TEXT(tbl_die_ordering[[#This Row],[Die Requested Date]],"mmm") -> Jan | AG4: =_xlfn.TEXTJOIN("_",TRUE,tbl_die_ordering[[#This Row],[Supplier]],tbl_die_ordering[[#This Row],[DIE NO]]) -> EKSTEK_01001-402
A5: GEX 1 | B5: =_xlfn.XLOOKUP(_xlfn.TEXTJOIN("_",TRUE,tbl_die_ordering[[#This Row],[Supplier]],tbl_die_ordering[[#This Row],[DIE NO]]),[1]Tracker!$AQ:$AQ,[1]Tracker!$W:$W,"") -> 7610-25 | C5: 14940-509 | D5: B | E5: 320X160 | F5: 45660 | G5: =_xlfn.XLOOKUP(_xlfn.TEXTJOIN("_",TRUE,tbl_die_ordering[[#This Row],[Supplier]],tbl_die_ordering[[#This Row],[DIE NO]]),[1]Tracker!$AQ:$AQ,[1]Tracker!$V:$V,"") -> 45660 | H5: AIR | I5: 1 | J5: 1 | K5: 45660 | L5: 45661 | N5: =IFERROR(IF(tbl_die_ordering[[#This Row],[Design Approved Date]]<>"",L5-K5,""),"") -> 1 | O5: 45665 | P5: 45666 | Q5: 45665 | R5: 112500093 | S5: EKSTEK | T5: 45665 | W5: =_xlfn.LET( _xlpm.dieNo, tbl_die_ordering[[#This Row],[DIE NO]], _xlpm.orderNo, tbl_die_ordering[[#This Row],[Order No]], _xlpm.type, tbl_die_ordering[[#This Row],[TYPE]], _xlpm.designReceived, tbl_die_ordering[[#This Row],[Design Received Date]], _xlpm.designApproved, tbl_die_ordering[[#This Row],[Design Approved Date]], _xlpm.sim, tbl_die_ordering[[#This Row],[Sim]], _xlpm.prEntry, tbl_die_ordering[[#This Row],[PR Entry]], _xlpm.oracleEntry, tbl_die_ordering[[#This Row],[Oracle Entry]], _xlpm.ems, tbl_die_ordering[[#This Row],[Design saved to EMS FOLDER]], IF(_xlpm.dieNo = "", "", IF(_xlpm.orderNo = "", "PENDING FOR ORDERING", IF(_xlpm.type = "C", "CANCELLED", IF(_xlpm.type = "H", "HOLD", IF(_xlpm.designReceived = "", "AWAITING FOR DESIGN", IF(_xlpm.designApproved = "", IF(_xlpm.sim = "YES", "UNDER SIMULATION", "PENDING FOR DESIGN APPROVAL"), IF(_xlpm.prEntry = "", "PENDING FOR PR", IF(_xlpm.oracleEntry = "", "PENDING FOR ORACLE ENTRY", IF(_xlpm.ems = "", "PENDING FOR DESIGN TO EMS", "DONE"))))))))) ) -> DONE | X5: =IF(AND(tbl_die_ordering[[#This Row],[TYPE]]<>"C",tbl_die_ordering[[#This Row],[Design Approved Date]]<>""),tbl_die_ordering[[#This Row],[Design Approved Date]]-tbl_die_ordering[[#This Row],[Die Requested Date]],0) -> 1 | AB5: =_xlfn.XLOOKUP(_xlfn.TEXTJOIN("_",TRUE,tbl_die_ordering[[#This Row],[Supplier]],tbl_die_ordering[[#This Row],[DIE NO]]),[1]Tracker!$AQ:$AQ,[1]Tracker!$Y:$Y,"") -> 142500488 | AC5: =_xlfn.XLOOKUP(_xlfn.TEXTJOIN("_",TRUE,tbl_die_ordering[[#This Row],[Supplier]],tbl_die_ordering[[#This Row],[DIE NO]]),[1]Tracker!$AQ:$AQ,[1]Tracker!$AC:$AC,"") -> 45681 | AF5: =TEXT(tbl_die_ordering[[#This Row],[Die Requested Date]],"mmm") -> Jan | AG5: =_xlfn.TEXTJOIN("_",TRUE,tbl_die_ordering[[#This Row],[Supplier]],tbl_die_ordering[[#This Row],[DIE NO]]) -> EKSTEK_14940-509
A6: GEX 1 | B6: =_xlfn.XLOOKUP(_xlfn.TEXTJOIN("_",TRUE,tbl_die_ordering[[#This Row],[Supplier]],tbl_die_ordering[[#This Row],[DIE NO]]),[1]Tracker!$AQ:$AQ,[1]Tracker!$W:$W,"") -> 7612-25 | C6: 27562-502 | D6: B | E6: 320X160 | F6: 45660 | G6: =_xlfn.XLOOKUP(_xlfn.TEXTJOIN("_",TRUE,tbl_die_ordering[[#This Row],[Supplier]],tbl_die_ordering[[#This Row],[DIE NO]]),[1]Tracker!$AQ:$AQ,[1]Tracker!$V:$V,"") -> 45660 | H6: AIR | I6: 0 | J6: 0 | K6: 45660 | L6: 45661 | N6: =IFERROR(IF(tbl_die_ordering[[#This Row],[Design Approved Date]]<>"",L6-K6,""),"") -> 1 | O6: 45665 | P6: 45666 | Q6: 45665 | R6: 112500093 | S6: PHOENIX | T6: 45665 | W6: =_xlfn.LET( _xlpm.dieNo, tbl_die_ordering[[#This Row],[DIE NO]], _xlpm.orderNo, tbl_die_ordering[[#This Row],[Order No]], _xlpm.type, tbl_die_ordering[[#This Row],[TYPE]], _xlpm.designReceived, tbl_die_ordering[[#This Row],[Design Received Date]], _xlpm.designApproved, tbl_die_ordering[[#This Row],[Design Approved Date]], _xlpm.sim, tbl_die_ordering[[#This Row],[Sim]], _xlpm.prEntry, tbl_die_ordering[[#This Row],[PR Entry]], _xlpm.oracleEntry, tbl_die_ordering[[#This Row],[Oracle Entry]], _xlpm.ems, tbl_die_ordering[[#This Row],[Design saved to EMS FOLDER]], IF(_xlpm.dieNo = "", "", IF(_xlpm.orderNo = "", "PENDING FOR ORDERING", IF(_xlpm.type = "C", "CANCELLED", IF(_xlpm.type = "H", "HOLD", IF(_xlpm.designReceived = "", "AWAITING FOR DESIGN", IF(_xlpm.designApproved = "", IF(_xlpm.sim = "YES", "UNDER SIMULATION", "PENDING FOR DESIGN APPROVAL"), IF(_xlpm.prEntry = "", "PENDING FOR PR", IF(_xlpm.oracleEntry = "", "PENDING FOR ORACLE ENTRY", IF(_xlpm.ems = "", "PENDING FOR DESIGN TO EMS", "DONE"))))))))) ) -> DONE | X6: =IF(AND(tbl_die_ordering[[#This Row],[TYPE]]<>"C",tbl_die_ordering[[#This Row],[Design Approved Date]]<>""),tbl_die_ordering[[#This Row],[Design Approved Date]]-tbl_die_ordering[[#This Row],[Die Requested Date]],0) -> 1 | AB6: =_xlfn.XLOOKUP(_xlfn.TEXTJOIN("_",TRUE,tbl_die_ordering[[#This Row],[Supplier]],tbl_die_ordering[[#This Row],[DIE NO]]),[1]Tracker!$AQ:$AQ,[1]Tracker!$Y:$Y,"") -> 142500502 | AC6: =_xlfn.XLOOKUP(_xlfn.TEXTJOIN("_",TRUE,tbl_die_ordering[[#This Row],[Supplier]],tbl_die_ordering[[#This Row],[DIE NO]]),[1]Tracker!$AQ:$AQ,[1]Tracker!$AC:$AC,"") -> 45684 | AF6: =TEXT(tbl_die_ordering[[#This Row],[Die Requested Date]],"mmm") -> Jan | AG6: =_xlfn.TEXTJOIN("_",TRUE,tbl_die_ordering[[#This Row],[Supplier]],tbl_die_ordering[[#This Row],[DIE NO]]) -> PHOENIX _27562-502
A7: GEX 1 | B7: =_xlfn.XLOOKUP(_xlfn.TEXTJOIN("_",TRUE,tbl_die_ordering[[#This Row],[Supplier]],tbl_die_ordering[[#This Row],[DIE NO]]),[1]Tracker!$AQ:$AQ,[1]Tracker!$W:$W,"") -> 7612-25 | C7: 27660-202 | D7: B | E7: 355X200 | F7: 45660 | G7: =_xlfn.XLOOKUP(_xlfn.TEXTJOIN("_",TRUE,tbl_die_ordering[[#This Row],[Supplier]],tbl_die_ordering[[#This Row],[DIE NO]]),[1]Tracker!$AQ:$AQ,[1]Tracker!$V:$V,"") -> 45660 | H7: AIR | I7: 0 | J7: 0 | K7: 45660 | L7: 45661 | N7: =IFERROR(IF(tbl_die_ordering[[#This Row],[Design Approved Date]]<>"",L7-K7,""),"") -> 1 | O7: 45665 | P7: 45666 | Q7: 45665 | R7: 112500093 | S7: PHOENIX | T7: 45665 | W7: =_xlfn.LET( _xlpm.dieNo, tbl_die_ordering[[#This Row],[DIE NO]], _xlpm.orderNo, tbl_die_ordering[[#This Row],[Order No]], _xlpm.type, tbl_die_ordering[[#This Row],[TYPE]], _xlpm.designReceived, tbl_die_ordering[[#This Row],[Design Received Date]], _xlpm.designApproved, tbl_die_ordering[[#This Row],[Design Approved Date]], _xlpm.sim, tbl_die_ordering[[#This Row],[Sim]], _xlpm.prEntry, tbl_die_ordering[[#This Row],[PR Entry]], _xlpm.oracleEntry, tbl_die_ordering[[#This Row],[Oracle Entry]], _xlpm.ems, tbl_die_ordering[[#This Row],[Design saved to EMS FOLDER]], IF(_xlpm.dieNo = "", "", IF(_xlpm.orderNo = "", "PENDING FOR ORDERING", IF(_xlpm.type = "C", "CANCELLED", IF(_xlpm.type = "H", "HOLD", IF(_xlpm.designReceived = "", "AWAITING FOR DESIGN", IF(_xlpm.designApproved = "", IF(_xlpm.sim = "YES", "UNDER SIMULATION", "PENDING FOR DESIGN APPROVAL"), IF(_xlpm.prEntry = "", "PENDING FOR PR", IF(_xlpm.oracleEntry = "", "PENDING FOR ORACLE ENTRY", IF(_xlpm.ems = "", "PENDING FOR DESIGN TO EMS", "DONE"))))))))) ) -> DONE | X7: =IF(AND(tbl_die_ordering[[#This Row],[TYPE]]<>"C",tbl_die_ordering[[#This Row],[Design Approved Date]]<>""),tbl_die_ordering[[#This Row],[Design Approved Date]]-tbl_die_ordering[[#This Row],[Die Requested Date]],0) -> 1 | AB7: =_xlfn.XLOOKUP(_xlfn.TEXTJOIN("_",TRUE,tbl_die_ordering[[#This Row],[Supplier]],tbl_die_ordering[[#This Row],[DIE NO]]),[1]Tracker!$AQ:$AQ,[1]Tracker!$Y:$Y,"") -> 142500502 | AC7: =_xlfn.XLOOKUP(_xlfn.TEXTJOIN("_",TRUE,tbl_die_ordering[[#This Row],[Supplier]],tbl_die_ordering[[#This Row],[DIE NO]]),[1]Tracker!$AQ:$AQ,[1]Tracker!$AC:$AC,"") -> 45684 | AF7: =TEXT(tbl_die_ordering[[#This Row],[Die Requested Date]],"mmm") -> Jan | AG7: =_xlfn.TEXTJOIN("_",TRUE,tbl_die_ordering[[#This Row],[Supplier]],tbl_die_ordering[[#This Row],[DIE NO]]) -> PHOENIX _27660-202
A8: GEX 1 | B8: =_xlfn.XLOOKUP(_xlfn.TEXTJOIN("_",TRUE,tbl_die_ordering[[#This Row],[Supplier]],tbl_die_ordering[[#This Row],[DIE NO]]),[1]Tracker!$AQ:$AQ,[1]Tracker!$W:$W,"") -> 7613-25 | C8: BOL-6-2-B | D8: T | E8: 700X196 | F8: 45660 | G8: =_xlfn.XLOOKUP(_xlfn.TEXTJOIN("_",TRUE,tbl_die_ordering[[#This Row],[Supplier]],tbl_die_ordering[[#This Row],[DIE NO]]),[1]Tracker!$AQ:$AQ,[1]Tracker!$V:$V,"") -> 45660 | H8: LAND | I8: 0 | J8: 0 | K8: 45663 | L8: 45663 | N8: =IFERROR(IF(tbl_die_ordering[[#This Row],[Design Approved Date]]<>"",L8-K8,""),"") -> 0 | O8: 45665 | P8: 45665 | Q8: 45665 | R8: 112500093 | S8: PDTMC | T8: 45667 | W8: =_xlfn.LET( _xlpm.dieNo, tbl_die_ordering[[#This Row],[DIE NO]], _xlpm.orderNo, tbl_die_ordering[[#This Row],[Order No]], _xlpm.type, tbl_die_ordering[[#This Row],[TYPE]], _xlpm.designReceived, tbl_die_ordering[[#This Row],[Design Received Date]], _xlpm.designApproved, tbl_die_ordering[[#This Row],[Design Approved Date]], _xlpm.sim, tbl_die_ordering[[#This Row],[Sim]], _xlpm.prEntry, tbl_die_ordering[[#This Row],[PR Entry]], _xlpm.oracleEntry, tbl_die_ordering[[#This Row],[Oracle Entry]], _xlpm.ems, tbl_die_ordering[[#This Row],[Design saved to EMS FOLDER]], IF(_xlpm.dieNo = "", "", IF(_xlpm.orderNo = "", "PENDING FOR ORDERING", IF(_xlpm.type = "C", "CANCELLED", IF(_xlpm.type = "H", "HOLD", IF(_xlpm.designReceived = "", "AWAITING FOR DESIGN", IF(_xlpm.designApproved = "", IF(_xlpm.sim = "YES", "UNDER SIMULATION", "PENDING FOR DESIGN APPROVAL"), IF(_xlpm.prEntry = "", "PENDING FOR PR", IF(_xlpm.oracleEntry = "", "PENDING FOR ORACLE ENTRY", IF(_xlpm.ems = "", "PENDING FOR DESIGN TO EMS", "DONE"))))))))) ) -> DONE | X8: =IF(AND(tbl_die_ordering[[#This Row],[TYPE]]<>"C",tbl_die_ordering[[#This Row],[Design Approved Date]]<>""),tbl_die_ordering[[#This Row],[Design Approved Date]]-tbl_die_ordering[[#This Row],[Die Requested Date]],0) -> 3 | AB8: =_xlfn.XLOOKUP(_xlfn.TEXTJOIN("_",TRUE,tbl_die_ordering[[#This Row],[Supplier]],tbl_die_ordering[[#This Row],[DIE NO]]),[1]Tracker!$AQ:$AQ,[1]Tracker!$Y:$Y,"") -> 142500499 | AC8: =_xlfn.XLOOKUP(_xlfn.TEXTJOIN("_",TRUE,tbl_die_ordering[[#This Row],[Supplier]],tbl_die_ordering[[#This Row],[DIE NO]]),[1]Tracker!$AQ:$AQ,[1]Tracker!$AC:$AC,"") -> 45762 | AF8: =TEXT(tbl_die_ordering[[#This Row],[Die Requested Date]],"mmm") -> Jan | AG8: =_xlfn.TEXTJOIN("_",TRUE,tbl_die_ordering[[#This Row],[Supplier]],tbl_die_ordering[[#This Row],[DIE NO]]) -> PDTMC_BOL-6-2-B
A9: GEX 1 | B9: =_xlfn.XLOOKUP(_xlfn.TEXTJOIN("_",TRUE,tbl_die_ordering[[#This Row],[Supplier]],tbl_die_ordering[[#This Row],[DIE NO]]),[1]Tracker!$AQ:$AQ,[1]Tracker!$W:$W,"") -> 7611-25 | C9: 10485-501 | D9: B | E9: 220X130 | F9: 45660 | G9: =_xlfn.XLOOKUP(_xlfn.TEXTJOIN("_",TRUE,tbl_die_ordering[[#This Row],[Supplier]],tbl_die_ordering[[#This Row],[DIE NO]]),[1]Tracker!$AQ:$AQ,[1]Tracker!$V:$V,"") -> 45660 | H9: LAND | I9: 0 | J9: 0 | K9: 45665 | L9: 45666 | N9: =IFERROR(IF(tbl_die_ordering[[#This Row],[Design Approved Date]]<>"",L9-K9,""),"") -> 1 | O9: 45667 | P9: 45670 | Q9: 45667 | R9: 112500165 | S9: PDTMC | T9: 45667 | W9: =_xlfn.LET( _xlpm.dieNo, tbl_die_ordering[[#This Row],[DIE NO]], _xlpm.orderNo, tbl_die_ordering[[#This Row],[Order No]], _xlpm.type, tbl_die_ordering[[#This Row],[TYPE]], _xlpm.designReceived, tbl_die_ordering[[#This Row],[Design Received Date]], _xlpm.designApproved, tbl_die_ordering[[#This Row],[Design Approved Date]], _xlpm.sim, tbl_die_ordering[[#This Row],[Sim]], _xlpm.prEntry, tbl_die_ordering[[#This Row],[PR Entry]], _xlpm.oracleEntry, tbl_die_ordering[[#This Row],[Oracle Entry]], _xlpm.ems, tbl_die_ordering[[#This Row],[Design saved to EMS FOLDER]], IF(_xlpm.dieNo = "", "", IF(_xlpm.orderNo = "", "PENDING FOR ORDERING", IF(_xlpm.type = "C", "CANCELLED", IF(_xlpm.type = "H", "HOLD", IF(_xlpm.designReceived = "", "AWAITING FOR DESIGN", IF(_xlpm.designApproved = "", IF(_xlpm.sim = "YES", "UNDER SIMULATION", "PENDING FOR DESIGN APPROVAL"), IF(_xlpm.prEntry = "", "PENDING FOR PR", IF(_xlpm.oracleEntry = "", "PENDING FOR ORACLE ENTRY", IF(_xlpm.ems = "", "PENDING FOR DESIGN TO EMS", "DONE"))))))))) ) -> DONE | X9: =IF(AND(tbl_die_ordering[[#This Row],[TYPE]]<>"C",tbl_die_ordering[[#This Row],[Design Approved Date]]<>""),tbl_die_ordering[[#This Row],[Design Approved Date]]-tbl_die_ordering[[#This Row],[Die Requested Date]],0) -> 6 | AB9: =_xlfn.XLOOKUP(_xlfn.TEXTJOIN("_",TRUE,tbl_die_ordering[[#This Row],[Supplier]],tbl_die_ordering[[#This Row],[DIE NO]]),[1]Tracker!$AQ:$AQ,[1]Tracker!$Y:$Y,"") -> 142500703 | AC9: =_xlfn.XLOOKUP(_xlfn.TEXTJOIN("_",TRUE,tbl_die_ordering[[#This Row],[Supplier]],tbl_die_ordering[[#This Row],[DIE NO]]),[1]Tracker!$AQ:$AQ,[1]Tracker!$AC:$AC,"") -> 45683 | AF9: =TEXT(tbl_die_ordering[[#This Row],[Die Requested Date]],"mmm") -> Jan | AG9: =_xlfn.TEXTJOIN("_",TRUE,tbl_die_ordering[[#This Row],[Supplier]],tbl_die_ordering[[#This Row],[DIE NO]]) -> PDTMC_10485-501
A10: GEX 1 | B10: =_xlfn.XLOOKUP(_xlfn.TEXTJOIN("_",TRUE,tbl_die_ordering[[#This Row],[Supplier]],tbl_die_ordering[[#This Row],[DIE NO]]),[1]Tracker!$AQ:$AQ,[1]Tracker!$W:$W,"") -> 7612-25 | C10: 13640-506 | D10: B | E10: 320X160 | F10: 45660 | G10: =_xlfn.XLOOKUP(_xlfn.TEXTJOIN("_",TRUE,tbl_die_ordering[[#This Row],[Supplier]],tbl_die_ordering[[#This Row],[DIE NO]]),[1]Tracker!$AQ:$AQ,[1]Tracker!$V:$V,"") -> 45660 | H10: AIR | I10: 1 | J10: 2 | K10: 45664 | L10: 45666 | N10: =IFERROR(IF(tbl_die_ordering[[#This Row],[Design Approved Date]]<>"",L10-K10,""),"") -> 2 | O10: 45667 | P10: 45670 | Q10: 45667 | R10: 112500165 | S10: PHOENIX | T10: 45667 | W10: =_xlfn.LET( _xlpm.dieNo, tbl_die_ordering[[#This Row],[DIE NO]], _xlpm.orderNo, tbl_die_ordering[[#This Row],[Order No]], _xlpm.type, tbl_die_ordering[[#This Row],[TYPE]], _xlpm.designReceived, tbl_die_ordering[[#This Row],[Design Received Date]], _xlpm.designApproved, tbl_die_ordering[[#This Row],[Design Approved Date]], _xlpm.sim, tbl_die_ordering[[#This Row],[Sim]], _xlpm.prEntry, tbl_die_ordering[[#This Row],[PR Entry]], _xlpm.oracleEntry, tbl_die_ordering[[#This Row],[Oracle Entry]], _xlpm.ems, tbl_die_ordering[[#This Row],[Design saved to EMS FOLDER]], IF(_xlpm.dieNo = "", "", IF(_xlpm.orderNo = "", "PENDING FOR ORDERING", IF(_xlpm.type = "C", "CANCELLED", IF(_xlpm.type = "H", "HOLD", IF(_xlpm.designReceived = "", "AWAITING FOR DESIGN", IF(_xlpm.designApproved = "", IF(_xlpm.sim = "YES", "UNDER SIMULATION", "PENDING FOR DESIGN APPROVAL"), IF(_xlpm.prEntry = "", "PENDING FOR PR", IF(_xlpm.oracleEntry = "", "PENDING FOR ORACLE ENTRY", IF(_xlpm.ems = "", "PENDING FOR DESIGN TO EMS", "DONE"))))))))) ) -> DONE | X10: =IF(AND(tbl_die_ordering[[#This Row],[TYPE]]<>"C",tbl_die_ordering[[#This Row],[Design Approved Date]]<>""),tbl_die_ordering[[#This Row],[Design Approved Date]]-tbl_die_ordering[[#This Row],[Die Requested Date]],0) -> 6 | AB10: =_xlfn.XLOOKUP(_xlfn.TEXTJOIN("_",TRUE,tbl_die_ordering[[#This Row],[Supplier]],tbl_die_ordering[[#This Row],[DIE NO]]),[1]Tracker!$AQ:$AQ,[1]Tracker!$Y:$Y,"") -> 142500603 | AC10: =_xlfn.XLOOKUP(_xlfn.TEXTJOIN("_",TRUE,tbl_die_ordering[[#This Row],[Supplier]],tbl_die_ordering[[#This Row],[DIE NO]]),[1]Tracker!$AQ:$AQ,[1]Tracker!$AC:$AC,"") -> 45684 | AF10: =TEXT(tbl_die_ordering[[#This Row],[Die Requested Date]],"mmm") -> Jan | AG10: =_xlfn.TEXTJOIN("_",TRUE,tbl_die_ordering[[#This Row],[Supplier]],tbl_die_ordering[[#This Row],[DIE NO]]) -> PHOENIX _13640-506
A11: GEX 1 | B11: =_xlfn.XLOOKUP(_xlfn.TEXTJOIN("_",TRUE,tbl_die_ordering[[#This Row],[Supplier]],tbl_die_ordering[[#This Row],[DIE NO]]),[1]Tracker!$AQ:$AQ,[1]Tracker!$W:$W,"") -> 7612-25 | C11: 14853-204 | D11: B | E11: 280X160 | F11: 45660 | G11: =_xlfn.XLOOKUP(_xlfn.TEXTJOIN("_",TRUE,tbl_die_ordering[[#This Row],[Supplier]],tbl_die_ordering[[#This Row],[DIE NO]]),[1]Tracker!$AQ:$AQ,[1]Tracker!$V:$V,"") -> 45660 | H11: AIR | I11: 4 | J11: 8 | K11: 45664 | L11: 45666 | N11: =IFERROR(IF(tbl_die_ordering[[#This Row],[Design Approved Date]]<>"",L11-K11,""),"") -> 2 | O11: 45667 | P11: 45670 | Q11: 45667 | R11: 112500165 | S11: PHOENIX | T11: 45667 | W11: =_xlfn.LET( _xlpm.dieNo, tbl_die_ordering[[#This Row],[DIE NO]], _xlpm.orderNo, tbl_die_ordering[[#This Row],[Order No]], _xlpm.type, tbl_die_ordering[[#This Row],[TYPE]], _xlpm.designReceived, tbl_die_ordering[[#This Row],[Design Received Date]], _xlpm.designApproved, tbl_die_ordering[[#This Row],[Design Approved Date]], _xlpm.sim, tbl_die_ordering[[#This Row],[Sim]], _xlpm.prEntry, tbl_die_ordering[[#This Row],[PR Entry]], _xlpm.oracleEntry, tbl_die_ordering[[#This Row],[Oracle Entry]], _xlpm.ems, tbl_die_ordering[[#This Row],[Design saved to EMS FOLDER]], IF(_xlpm.dieNo = "", "", IF(_xlpm.orderNo = "", "PENDING FOR ORDERING", IF(_xlpm.type = "C", "CANCELLED", IF(_xlpm.type = "H", "HOLD", IF(_xlpm.designReceived = "", "AWAITING FOR DESIGN", IF(_xlpm.designApproved = "", IF(_xlpm.sim = "YES", "UNDER SIMULATION", "PENDING FOR DESIGN APPROVAL"), IF(_xlpm.prEntry = "", "PENDING FOR PR", IF(_xlpm.oracleEntry = "", "PENDING FOR ORACLE ENTRY", IF(_xlpm.ems = "", "PENDING FOR DESIGN TO EMS", "DONE"))))))))) ) -> DONE | X11: =IF(AND(tbl_die_ordering[[#This Row],[TYPE]]<>"C",tbl_die_ordering[[#This Row],[Design Approved Date]]<>""),tbl_die_ordering[[#This Row],[Design Approved Date]]-tbl_die_ordering[[#This Row],[Die Requested Date]],0) -> 6 | AB11: =_xlfn.XLOOKUP(_xlfn.TEXTJOIN("_",TRUE,tbl_die_ordering[[#This Row],[Supplier]],tbl_die_ordering[[#This Row],[DIE NO]]),[1]Tracker!$AQ:$AQ,[1]Tracker!$Y:$Y,"") -> 142500603 | AC11: =_xlfn.XLOOKUP(_xlfn.TEXTJOIN("_",TRUE,tbl_die_ordering[[#This Row],[Supplier]],tbl_die_ordering[[#This Row],[DIE NO]]),[1]Tracker!$AQ:$AQ,[1]Tracker!$AC:$AC,"") -> 45684 | AF11: =TEXT(tbl_die_ordering[[#This Row],[Die Requested Date]],"mmm") -> Jan | AG11: =_xlfn.TEXTJOIN("_",TRUE,tbl_die_ordering[[#This Row],[Supplier]],tbl_die_ordering[[#This Row],[DIE NO]]) -> PHOENIX _14853-204
A12: GEX 1 | B12: =_xlfn.XLOOKUP(_xlfn.TEXTJOIN("_",TRUE,tbl_die_ordering[[#This Row],[Supplier]],tbl_die_ordering[[#This Row],[DIE NO]]),[1]Tracker!$AQ:$AQ,[1]Tracker!$W:$W,"") -> 7612-25 | C12: 19105-403 | D12: B | E12: 250X160 | F12: 45660 | G12: =_xlfn.XLOOKUP(_xlfn.TEXTJOIN("_",TRUE,tbl_die_ordering[[#This Row],[Supplier]],tbl_die_ordering[[#This Row],[DIE NO]]),[1]Tracker!$AQ:$AQ,[1]Tracker!$V:$V,"") -> 45660 | H12: AIR | I12: 1 | J12: 2 | K12: 45664 | L12: 45666 | N12: =IFERROR(IF(tbl_die_ordering[[#This Row],[Design Approved Date]]<>"",L12-K12,""),"") -> 2 | O12: 45667 | P12: 45670 | Q12: 45667 | R12: 112500165 | S12: PHOENIX | T12: 45667 | W12: =_xlfn.LET( _xlpm.dieNo, tbl_die_ordering[[#This Row],[DIE NO]], _xlpm.orderNo, tbl_die_ordering[[#This Row],[Order No]], _xlpm.type, tbl_die_ordering[[#This Row],[TYPE]], _xlpm.designReceived, tbl_die_ordering[[#This Row],[Design Received Date]], _xlpm.designApproved, tbl_die_ordering[[#This Row],[Design Approved Date]], _xlpm.sim, tbl_die_ordering[[#This Row],[Sim]], _xlpm.prEntry, tbl_die_ordering[[#This Row],[PR Entry]], _xlpm.oracleEntry, tbl_die_ordering[[#This Row],[Oracle Entry]], _xlpm.ems, tbl_die_ordering[[#This Row],[Design saved to EMS FOLDER]], IF(_xlpm.dieNo = "", "", IF(_xlpm.orderNo = "", "PENDING FOR ORDERING", IF(_xlpm.type = "C", "CANCELLED", IF(_xlpm.type = "H", "HOLD", IF(_xlpm.designReceived = "", "AWAITING FOR DESIGN", IF(_xlpm.designApproved = "", IF(_xlpm.sim = "YES", "UNDER SIMULATION", "PENDING FOR DESIGN APPROVAL"), IF(_xlpm.prEntry = "", "PENDING FOR PR", IF(_xlpm.oracleEntry = "", "PENDING FOR ORACLE ENTRY", IF(_xlpm.ems = "", "PENDING FOR DESIGN TO EMS", "DONE"))))))))) ) -> DONE | X12: =IF(AND(tbl_die_ordering[[#This Row],[TYPE]]<>"C",tbl_die_ordering[[#This Row],[Design Approved Date]]<>""),tbl_die_ordering[[#This Row],[Design Approved Date]]-tbl_die_ordering[[#This Row],[Die Requested Date]],0) -> 6 | AB12: =_xlfn.XLOOKUP(_xlfn.TEXTJOIN("_",TRUE,tbl_die_ordering[[#This Row],[Supplier]],tbl_die_ordering[[#This Row],[DIE NO]]),[1]Tracker!$AQ:$AQ,[1]Tracker!$Y:$Y,"") -> 142500603 | AC12: =_xlfn.XLOOKUP(_xlfn.TEXTJOIN("_",TRUE,tbl_die_ordering[[#This Row],[Supplier]],tbl_die_ordering[[#This Row],[DIE NO]]),[1]Tracker!$AQ:$AQ,[1]Tracker!$AC:$AC,"") -> 45684 | AF12: =TEXT(tbl_die_ordering[[#This Row],[Die Requested Date]],"mmm") -> Jan | AG12: =_xlfn.TEXTJOIN("_",TRUE,tbl_die_ordering[[#This Row],[Supplier]],tbl_die_ordering[[#This Row],[DIE NO]]) -> PHOENIX _19105-403
A13: GEX 1 | B13: =_xlfn.XLOOKUP(_xlfn.TEXTJOIN("_",TRUE,tbl_die_ordering[[#This Row],[Supplier]],tbl_die_ordering[[#This Row],[DIE NO]]),[1]Tracker!$AQ:$AQ,[1]Tracker!$W:$W,"") -> 7612-25 | C13: 28424-202 | D13: B | E13: 320X160 | F13: 45660 | G13: =_xlfn.XLOOKUP(_xlfn.TEXTJOIN("_",TRUE,tbl_die_ordering[[#This Row],[Supplier]],tbl_die_ordering[[#This Row],[DIE NO]]),[1]Tracker!$AQ:$AQ,[1]Tracker!$V:$V,"") -> 45660 | H13: AIR | I13: 1 | J13: 1 | K13: 45664 | L13: 45666 | N13: =IFERROR(IF(tbl_die_ordering[[#This Row],[Design Approved Date]]<>"",L13-K13,""),"") -> 2 | O13: 45667 | P13: 45670 | Q13: 45667 | R13: 112500165 | S13: PHOENIX | T13: 45667 | W13: =_xlfn.LET( _xlpm.dieNo, tbl_die_ordering[[#This Row],[DIE NO]], _xlpm.orderNo, tbl_die_ordering[[#This Row],[Order No]], _xlpm.type, tbl_die_ordering[[#This Row],[TYPE]], _xlpm.designReceived, tbl_die_ordering[[#This Row],[Design Received Date]], _xlpm.designApproved, tbl_die_ordering[[#This Row],[Design Approved Date]], _xlpm.sim, tbl_die_ordering[[#This Row],[Sim]], _xlpm.prEntry, tbl_die_ordering[[#This Row],[PR Entry]], _xlpm.oracleEntry, tbl_die_ordering[[#This Row],[Oracle Entry]], _xlpm.ems, tbl_die_ordering[[#This Row],[Design saved to EMS FOLDER]], IF(_xlpm.dieNo = "", "", IF(_xlpm.orderNo = "", "PENDING FOR ORDERING", IF(_xlpm.type = "C", "CANCELLED", IF(_xlpm.type = "H", "HOLD", IF(_xlpm.designReceived = "", "AWAITING FOR DESIGN", IF(_xlpm.designApproved = "", IF(_xlpm.sim = "YES", "UNDER SIMULATION", "PENDING FOR DESIGN APPROVAL"), IF(_xlpm.prEntry = "", "PENDING FOR PR", IF(_xlpm.oracleEntry = "", "PENDING FOR ORACLE ENTRY", IF(_xlpm.ems = "", "PENDING FOR DESIGN TO EMS", "DONE"))))))))) ) -> DONE | X13: =IF(AND(tbl_die_ordering[[#This Row],[TYPE]]<>"C",tbl_die_ordering[[#This Row],[Design Approved Date]]<>""),tbl_die_ordering[[#This Row],[Design Approved Date]]-tbl_die_ordering[[#This Row],[Die Requested Date]],0) -> 6 | AB13: =_xlfn.XLOOKUP(_xlfn.TEXTJOIN("_",TRUE,tbl_die_ordering[[#This Row],[Supplier]],tbl_die_ordering[[#This Row],[DIE NO]]),[1]Tracker!$AQ:$AQ,[1]Tracker!$Y:$Y,"") -> 142500701 | AC13: =_xlfn.XLOOKUP(_xlfn.TEXTJOIN("_",TRUE,tbl_die_ordering[[#This Row],[Supplier]],tbl_die_ordering[[#This Row],[DIE NO]]),[1]Tracker!$AQ:$AQ,[1]Tracker!$AC:$AC,"") -> 45684 | AF13: =TEXT(tbl_die_ordering[[#This Row],[Die Requested Date]],"mmm") -> Jan | AG13: =_xlfn.TEXTJOIN("_",TRUE,tbl_die_ordering[[#This Row],[Supplier]],tbl_die_ordering[[#This Row],[DIE NO]]) -> PHOENIX _28424-202
A14: GEX 1 | B14: =_xlfn.XLOOKUP(_xlfn.TEXTJOIN("_",TRUE,tbl_die_ordering[[#This Row],[Supplier]],tbl_die_ordering[[#This Row],[DIE NO]]),[1]Tracker!$AQ:$AQ,[1]Tracker!$W:$W,"") -> 7610-25 | C14: 12726-503 | D14: B | E14: 280X160 | F14: 45660 | G14: =_xlfn.XLOOKUP(_xlfn.TEXTJOIN("_",TRUE,tbl_die_ordering[[#This Row],[Supplier]],tbl_die_ordering[[#This Row],[DIE NO]]),[1]Tracker!$AQ:$AQ,[1]Tracker!$V:$V,"") -> 45660 | H14: AIR | I14: 1 | J14: 2 | K14: 45660 | L14: 45668 | N14: =IFERROR(IF(tbl_die_ordering[[#This Row],[Design Approved Date]]<>"",L14-K14,""),"") -> 8 | O14: 45670 | P14: 45670 | Q14: 45670 | R14: 112500175 | S14: EKSTEK | T14: 45670 | V14: desigh received on 03/01/2025 similar die is in simulation (14674-427) both dies will be sent for approval together 06/01/2025 | W14: =_xlfn.LET( _xlpm.dieNo, tbl_die_ordering[[#This Row],[DIE NO]], _xlpm.orderNo, tbl_die_ordering[[#This Row],[Order No]], _xlpm.type, tbl_die_ordering[[#This Row],[TYPE]], _xlpm.designReceived, tbl_die_ordering[[#This Row],[Design Received Date]], _xlpm.designApproved, tbl_die_ordering[[#This Row],[Design Approved Date]], _xlpm.sim, tbl_die_ordering[[#This Row],[Sim]], _xlpm.prEntry, tbl_die_ordering[[#This Row],[PR Entry]], _xlpm.oracleEntry, tbl_die_ordering[[#This Row],[Oracle Entry]], _xlpm.ems, tbl_die_ordering[[#This Row],[Design saved to EMS FOLDER]], IF(_xlpm.dieNo = "", "", IF(_xlpm.orderNo = "", "PENDING FOR ORDERING", IF(_xlpm.type = "C", "CANCELLED", IF(_xlpm.type = "H", "HOLD", IF(_xlpm.designReceived = "", "AWAITING FOR DESIGN", IF(_xlpm.designApproved = "", IF(_xlpm.sim = "YES", "UNDER SIMULATION", "PENDING FOR DESIGN APPROVAL"), IF(_xlpm.prEntry = "", "PENDING FOR PR", IF(_xlpm.oracleEntry = "", "PENDING FOR ORACLE ENTRY", IF(_xlpm.ems = "", "PENDING FOR DESIGN TO EMS", "DONE"))))))))) ) -> DONE | X14: =IF(AND(tbl_die_ordering[[#This Row],[TYPE]]<>"C",tbl_die_ordering[[#This Row],[Design Approved Date]]<>""),tbl_die_ordering[[#This Row],[Design Approved Date]]-tbl_die_ordering[[#This Row],[Die Requested Date]],0) -> 8 | AB14: =_xlfn.XLOOKUP(_xlfn.TEXTJOIN("_",TRUE,tbl_die_ordering[[#This Row],[Supplier]],tbl_die_ordering[[#This Row],[DIE NO]]),[1]Tracker!$AQ:$AQ,[1]Tracker!$Y:$Y,"") -> 142500487 | AC14: =_xlfn.XLOOKUP(_xlfn.TEXTJOIN("_",TRUE,tbl_die_ordering[[#This Row],[Supplier]],tbl_die_ordering[[#This Row],[DIE NO]]),[1]Tracker!$AQ:$AQ,[1]Tracker!$AC:$AC,"") -> 45676 | AF14: =TEXT(tbl_die_ordering[[#This Row],[Die Requested Date]],"mmm") -> Jan | AG14: =_xlfn.TEXTJOIN("_",TRUE,tbl_die_ordering[[#This Row],[Supplier]],tbl_die_ordering[[#This Row],[DIE NO]]) -> EKSTEK_12726-503
A15: GEX 1 | B15: =_xlfn.XLOOKUP(_xlfn.TEXTJOIN("_",TRUE,tbl_die_ordering[[#This Row],[Supplier]],tbl_die_ordering[[#This Row],[DIE NO]]),[1]Tracker!$AQ:$AQ,[1]Tracker!$W:$W,"") -> 7611-25 | C15: 05203-201 | D15: B | E15: 250X160 | F15: 45660 | G15: =_xlfn.XLOOKUP(_xlfn.TEXTJOIN("_",TRUE,tbl_die_ordering[[#This Row],[Supplier]],tbl_die_ordering[[#This Row],[DIE NO]]),[1]Tracker!$AQ:$AQ,[1]Tracker!$V:$V,"") -> 45660 | H15: LAND | I15: 1 | J15: 4 | K15: 45670 | L15: 45672 | N15: =IFERROR(IF(tbl_die_ordering[[#This Row],[Design Approved Date]]<>"",L15-K15,""),"") -> 2 | O15: 45673 | P15: 45675 | Q15: 45673 | R15: 112500254 | S15: PDTMC | T15: 45673 | V15: ask for revision 09/01/2025 | W15: =_xlfn.LET( _xlpm.dieNo, tbl_die_ordering[[#This Row],[DIE NO]], _xlpm.orderNo, tbl_die_ordering[[#This Row],[Order No]], _xlpm.type, tbl_die_ordering[[#This Row],[TYPE]], _xlpm.designReceived, tbl_die_ordering[[#This Row],[Design Received Date]], _xlpm.designApproved, tbl_die_ordering[[#This Row],[Design Approved Date]], _xlpm.sim, tbl_die_ordering[[#This Row],[Sim]], _xlpm.prEntry, tbl_die_ordering[[#This Row],[PR Entry]], _xlpm.oracleEntry, tbl_die_ordering[[#This Row],[Oracle Entry]], _xlpm.ems, tbl_die_ordering[[#This Row],[Design saved to EMS FOLDER]], IF(_xlpm.dieNo = "", "", IF(_xlpm.orderNo = "", "PENDING FOR ORDERING", IF(_xlpm.type = "C", "CANCELLED", IF(_xlpm.type = "H", "HOLD", IF(_xlpm.designReceived = "", "AWAITING FOR DESIGN", IF(_xlpm.designApproved = "", IF(_xlpm.sim = "YES", "UNDER SIMULATION", "PENDING FOR DESIGN APPROVAL"), IF(_xlpm.prEntry = "", "PENDING FOR PR", IF(_xlpm.oracleEntry = "", "PENDING FOR ORACLE ENTRY", IF(_xlpm.ems = "", "PENDING FOR DESIGN TO EMS", "DONE"))))))))) ) -> DONE | X15: =IF(AND(tbl_die_ordering[[#This Row],[TYPE]]<>"C",tbl_die_ordering[[#This Row],[Design Approved Date]]<>""),tbl_die_ordering[[#This Row],[Design Approved Date]]-tbl_die_ordering[[#This Row],[Die Requested Date]],0) -> 12 | AB15: =_xlfn.XLOOKUP(_xlfn.TEXTJOIN("_",TRUE,tbl_die_ordering[[#This Row],[Supplier]],tbl_die_ordering[[#This Row],[DIE NO]]),[1]Tracker!$AQ:$AQ,[1]Tracker!$Y:$Y,"") -> 142501911 | AC15: =_xlfn.XLOOKUP(_xlfn.TEXTJOIN("_",TRUE,tbl_die_ordering[[#This Row],[Supplier]],tbl_die_ordering[[#This Row],[DIE NO]]),[1]Tracker!$AQ:$AQ,[1]Tracker!$AC:$AC,"") -> 45719 | AE15: cav increased | AF15: =TEXT(tbl_die_ordering[[#This Row],[Die Requested Date]],"mmm") -> Jan | AG15: =_xlfn.TEXTJOIN("_",TRUE,tbl_die_ordering[[#This Row],[Supplier]],tbl_die_ordering[[#This Row],[DIE NO]]) -> PDTMC_05203-201
A16: GEX 1 | B16: =_xlfn.XLOOKUP(_xlfn.TEXTJOIN("_",TRUE,tbl_die_ordering[[#This Row],[Supplier]],tbl_die_ordering[[#This Row],[DIE NO]]),[1]Tracker!$AQ:$AQ,[1]Tracker!$W:$W,"") -> 7611-25 | C16: 12441-406 | D16: B | E16: 250X160 | F16: 45660 | G16: =_xlfn.XLOOKUP(_xlfn.TEXTJOIN("_",TRUE,tbl_die_ordering[[#This Row],[Supplier]],tbl_die_ordering[[#This Row],[DIE NO]]),[1]Tracker!$AQ:$AQ,[1]Tracker!$V:$V,"") -> 45660 | H16: LAND | I16: 1 | J16: 1 | K16: 45666 | L16: 45673 | N16: =IFERROR(IF(tbl_die_ordering[[#This Row],[Design Approved Date]]<>"",L16-K16,""),"") -> 7 | O16: 45675 | P16: 45675 | Q16: 45675 | R16: 112500275 | S16: PDTMC | T16: 45675 | W16: =_xlfn.LET( _xlpm.dieNo, tbl_die_ordering[[#This Row],[DIE NO]], _xlpm.orderNo, tbl_die_ordering[[#This Row],[Order No]], _xlpm.type, tbl_die_ordering[[#This Row],[TYPE]], _xlpm.designReceived, tbl_die_ordering[[#This Row],[Design Received Date]], _xlpm.designApproved, tbl_die_ordering[[#This Row],[Design Approved Date]], _xlpm.sim, tbl_die_ordering[[#This Row],[Sim]], _xlpm.prEntry, tbl_die_ordering[[#This Row],[PR Entry]], _xlpm.oracleEntry, tbl_die_ordering[[#This Row],[Oracle Entry]], _xlpm.ems, tbl_die_ordering[[#This Row],[Design saved to EMS FOLDER]], IF(_xlpm.dieNo = "", "", IF(_xlpm.orderNo = "", "PENDING FOR ORDERING", IF(_xlpm.type = "C", "CANCELLED", IF(_xlpm.type = "H", "HOLD", IF(_xlpm.designReceived = "", "AWAITING FOR DESIGN", IF(_xlpm.designApproved = "", IF(_xlpm.sim = "YES", "UNDER SIMULATION", "PENDING FOR DESIGN APPROVAL"), IF(_xlpm.prEntry = "", "PENDING FOR PR", IF(_xlpm.oracleEntry = "", "PENDING FOR ORACLE ENTRY", IF(_xlpm.ems = "", "PENDING FOR DESIGN TO EMS", "DONE"))))))))) ) -> DONE | X16: =IF(AND(tbl_die_ordering[[#This Row],[TYPE]]<>"C",tbl_die_ordering[[#This Row],[Design Approved Date]]<>""),tbl_die_ordering[[#This Row],[Design Approved Date]]-tbl_die_ordering[[#This Row],[Die Requested Date]],0) -> 13 | AB16: =_xlfn.XLOOKUP(_xlfn.TEXTJOIN("_",TRUE,tbl_die_ordering[[#This Row],[Supplier]],tbl_die_ordering[[#This Row],[DIE NO]]),[1]Tracker!$AQ:$AQ,[1]Tracker!$Y:$Y,"") -> 142500748 | AC16: =_xlfn.XLOOKUP(_xlfn.TEXTJOIN("_",TRUE,tbl_die_ordering[[#This Row],[Supplier]],tbl_die_ordering[[#This Row],[DIE NO]]),[1]Tracker!$AQ:$AQ,[1]Tracker!$AC:$AC,"") -> 45685 | AF16: =TEXT(tbl_die_ordering[[#This Row],[Die Requested Date]],"mmm") -> Jan | AG16: =_xlfn.TEXTJOIN("_",TRUE,tbl_die_ordering[[#This Row],[Supplier]],tbl_die_ordering[[#This Row],[DIE NO]]) -> PDTMC_12441-406
A17: GEX 1 | B17: =_xlfn.XLOOKUP(_xlfn.TEXTJOIN("_",TRUE,tbl_die_ordering[[#This Row],[Supplier]],tbl_die_ordering[[#This Row],[DIE NO]]),[1]Tracker!$AQ:$AQ,[1]Tracker!$W:$W,"") -> 7612-25 | C17: 14856-203 | D17: B | E17: 280X160 | F17: 45660 | G17: =_xlfn.XLOOKUP(_xlfn.TEXTJOIN("_",TRUE,tbl_die_ordering[[#This Row],[Supplier]],tbl_die_ordering[[#This Row],[DIE NO]]),[1]Tracker!$AQ:$AQ,[1]Tracker!$V:$V,"") -> 45660 | H17: AIR | I17: 1 | J17: 1 | K17: 45665 | L17: 45673 | N17: =IFERROR(IF(tbl_die_ordering[[#This Row],[Design Approved Date]]<>"",L17-K17,""),"") -> 8 | O17: 45675 | P17: 45675 | Q17: 45675 | R17: 112500275 | S17: PHOENIX | T17: 45675 | W17: =_xlfn.LET( _xlpm.dieNo, tbl_die_ordering[[#This Row],[DIE NO]], _xlpm.orderNo, tbl_die_ordering[[#This Row],[Order No]], _xlpm.type, tbl_die_ordering[[#This Row],[TYPE]], _xlpm.designReceived, tbl_die_ordering[[#This Row],[Design Received Date]], _xlpm.designApproved, tbl_die_ordering[[#This Row],[Design Approved Date]], _xlpm.sim, tbl_die_ordering[[#This Row],[Sim]], _xlpm.prEntry, tbl_die_ordering[[#This Row],[PR Entry]], _xlpm.oracleEntry, tbl_die_ordering[[#This Row],[Oracle Entry]], _xlpm.ems, tbl_die_ordering[[#This Row],[Design saved to EMS FOLDER]], IF(_xlpm.dieNo = "", "", IF(_xlpm.orderNo = "", "PENDING FOR ORDERING", IF(_xlpm.type = "C", "CANCELLED", IF(_xlpm.type = "H", "HOLD", IF(_xlpm.designReceived = "", "AWAITING FOR DESIGN", IF(_xlpm.designApproved = "", IF(_xlpm.sim = "YES", "UNDER SIMULATION", "PENDING FOR DESIGN APPROVAL"), IF(_xlpm.prEntry = "", "PENDING FOR PR", IF(_xlpm.oracleEntry = "", "PENDING FOR ORACLE ENTRY", IF(_xlpm.ems = "", "PENDING FOR DESIGN TO EMS", "DONE"))))))))) ) -> DONE | X17: =IF(AND(tbl_die_ordering[[#This Row],[TYPE]]<>"C",tbl_die_ordering[[#This Row],[Design Approved Date]]<>""),tbl_die_ordering[[#This Row],[Design Approved Date]]-tbl_die_ordering[[#This Row],[Die Requested Date]],0) -> 13 | AB17: =_xlfn.XLOOKUP(_xlfn.TEXTJOIN("_",TRUE,tbl_die_ordering[[#This Row],[Supplier]],tbl_die_ordering[[#This Row],[DIE NO]]),[1]Tracker!$AQ:$AQ,[1]Tracker!$Y:$Y,"") -> 142500749 | AC17: =_xlfn.XLOOKUP(_xlfn.TEXTJOIN("_",TRUE,tbl_die_ordering[[#This Row],[Supplier]],tbl_die_ordering[[#This Row],[DIE NO]]),[1]Tracker!$AQ:$AQ,[1]Tracker!$AC:$AC,"") -> 45685 | AF17: =TEXT(tbl_die_ordering[[#This Row],[Die Requested Date]],"mmm") -> Jan | AG17: =_xlfn.TEXTJOIN("_",TRUE,tbl_die_ordering[[#This Row],[Supplier]],tbl_die_ordering[[#This Row],[DIE NO]]) -> PHOENIX _14856-203
A18: GEX 1 | B18: =_xlfn.XLOOKUP(_xlfn.TEXTJOIN("_",TRUE,tbl_die_ordering[[#This Row],[Supplier]],tbl_die_ordering[[#This Row],[DIE NO]]),[1]Tracker!$AQ:$AQ,[1]Tracker!$W:$W,"") -> 7612-25 | C18: 14857-203 | D18: B | E18: 320X160 | F18: 45660 | G18: =_xlfn.XLOOKUP(_xlfn.TEXTJOIN("_",TRUE,tbl_die_ordering[[#This Row],[Supplier]],tbl_die_ordering[[#This Row],[DIE NO]]),[1]Tracker!$AQ:$AQ,[1]Tracker!$V:$V,"") -> 45660 | H18: AIR | I18: 1 | J18: 1 | K18: 45665 | L18: 45673 | N18: =IFERROR(IF(tbl_die_ordering[[#This Row],[Design Approved Date]]<>"",L18-K18,""),"") -> 8 | O18: 45675 | P18: 45675 | Q18: 45675 | R18: 112500275 | S18: PHOENIX | T18: 45675 | W18: =_xlfn.LET( _xlpm.dieNo, tbl_die_ordering[[#This Row],[DIE NO]], _xlpm.orderNo, tbl_die_ordering[[#This Row],[Order No]], _xlpm.type, tbl_die_ordering[[#This Row],[TYPE]], _xlpm.designReceived, tbl_die_ordering[[#This Row],[Design Received Date]], _xlpm.designApproved, tbl_die_ordering[[#This Row],[Design Approved Date]], _xlpm.sim, tbl_die_ordering[[#This Row],[Sim]], _xlpm.prEntry, tbl_die_ordering[[#This Row],[PR Entry]], _xlpm.oracleEntry, tbl_die_ordering[[#This Row],[Oracle Entry]], _xlpm.ems, tbl_die_ordering[[#This Row],[Design saved to EMS FOLDER]], IF(_xlpm.dieNo = "", "", IF(_xlpm.orderNo = "", "PENDING FOR ORDERING", IF(_xlpm.type = "C", "CANCELLED", IF(_xlpm.type = "H", "HOLD", IF(_xlpm.designReceived = "", "AWAITING FOR DESIGN", IF(_xlpm.designApproved = "", IF(_xlpm.sim = "YES", "UNDER SIMULATION", "PENDING FOR DESIGN APPROVAL"), IF(_xlpm.prEntry = "", "PENDING FOR PR", IF(_xlpm.oracleEntry = "", "PENDING FOR ORACLE ENTRY", IF(_xlpm.ems = "", "PENDING FOR DESIGN TO EMS", "DONE"))))))))) ) -> DONE | X18: =IF(AND(tbl_die_ordering[[#This Row],[TYPE]]<>"C",tbl_die_ordering[[#This Row],[Design Approved Date]]<>""),tbl_die_ordering[[#This Row],[Design Approved Date]]-tbl_die_ordering[[#This Row],[Die Requested Date]],0) -> 13 | AB18: =_xlfn.XLOOKUP(_xlfn.TEXTJOIN("_",TRUE,tbl_die_ordering[[#This Row],[Supplier]],tbl_die_ordering[[#This Row],[DIE NO]]),[1]Tracker!$AQ:$AQ,[1]Tracker!$Y:$Y,"") -> 142500749 | AC18: =_xlfn.XLOOKUP(_xlfn.TEXTJOIN("_",TRUE,tbl_die_ordering[[#This Row],[Supplier]],tbl_die_ordering[[#This Row],[DIE NO]]),[1]Tracker!$AQ:$AQ,[1]Tracker!$AC:$AC,"") -> 45685 | AF18: =TEXT(tbl_die_ordering[[#This Row],[Die Requested Date]],"mmm") -> Jan | AG18: =_xlfn.TEXTJOIN("_",TRUE,tbl_die_ordering[[#This Row],[Supplier]],tbl_die_ordering[[#This Row],[DIE NO]]) -> PHOENIX _14857-203
A19: GEX 2 | B19: =_xlfn.XLOOKUP(_xlfn.TEXTJOIN("_",TRUE,tbl_die_ordering[[#This Row],[Supplier]],tbl_die_ordering[[#This Row],[DIE NO]]),[1]Tracker!$AQ:$AQ,[1]Tracker!$W:$W,"") -> 7614-25 | C19: 051137-2501 | D19: N | E19: 280X165 | F19: 45663 | G19: =_xlfn.XLOOKUP(_xlfn.TEXTJOIN("_",TRUE,tbl_die_ordering[[#This Row],[Supplier]],tbl_die_ordering[[#This Row],[DIE NO]]),[1]Tracker!$AQ:$AQ,[1]Tracker!$V:$V,"") -> 45663 | H19: LAND | I19: 1 | J19: 1 | K19: 45665 | L19: 45668 | M19: YES | N19: =IFERROR(IF(tbl_die_ordering[[#This Row],[Design Approved Date]]<>"",L19-K19,""),"") -> 3 | O19: 45671 | P19: 45674 | Q19: 45671 | R19: 1300001099 | S19: PDTMC | T19: 45674 | U19: APT | W19: =_xlfn.LET( _xlpm.dieNo, tbl_die_ordering[[#This Row],[DIE NO]], _xlpm.orderNo, tbl_die_ordering[[#This Row],[Order No]], _xlpm.type, tbl_die_ordering[[#This Row],[TYPE]], _xlpm.designReceived, tbl_die_ordering[[#This Row],[Design Received Date]], _xlpm.designApproved, tbl_die_ordering[[#This Row],[Design Approved Date]], _xlpm.sim, tbl_die_ordering[[#This Row],[Sim]], _xlpm.prEntry, tbl_die_ordering[[#This Row],[PR Entry]], _xlpm.oracleEntry, tbl_die_ordering[[#This Row],[Oracle Entry]], _xlpm.ems, tbl_die_ordering[[#This Row],[Design saved to EMS FOLDER]], IF(_xlpm.dieNo = "", "", IF(_xlpm.orderNo = "", "PENDING FOR ORDERING", IF(_xlpm.type = "C", "CANCELLED", IF(_xlpm.type = "H", "HOLD", IF(_xlpm.designReceived = "", "AWAITING FOR DESIGN", IF(_xlpm.designApproved = "", IF(_xlpm.sim = "YES", "UNDER SIMULATION", "PENDING FOR DESIGN APPROVAL"), IF(_xlpm.prEntry = "", "PENDING FOR PR", IF(_xlpm.oracleEntry = "", "PENDING FOR ORACLE ENTRY", IF(_xlpm.ems = "", "PENDING FOR DESIGN TO EMS", "DONE"))))))))) ) -> DONE | X19: =IF(AND(tbl_die_ordering[[#This Row],[TYPE]]<>"C",tbl_die_ordering[[#This Row],[Design Approved Date]]<>""),tbl_die_ordering[[#This Row],[Design Approved Date]]-tbl_die_ordering[[#This Row],[Die Requested Date]],0) -> 5 | AB19: =_xlfn.XLOOKUP(_xlfn.TEXTJOIN("_",TRUE,tbl_die_ordering[[#This Row],[Supplier]],tbl_die_ordering[[#This Row],[DIE NO]]),[1]Tracker!$AQ:$AQ,[1]Tracker!$Y:$Y,"") -> M124 | AC19: =_xlfn.XLOOKUP(_xlfn.TEXTJOIN("_",TRUE,tbl_die_ordering[[#This Row],[Supplier]],tbl_die_ordering[[#This Row],[DIE NO]]),[1]Tracker!$AQ:$AQ,[1]Tracker!$AC:$AC,"") -> 45693 | AF19: =TEXT(tbl_die_ordering[[#This Row],[Die Requested Date]],"mmm") -> Jan | AG19: =_xlfn.TEXTJOIN("_",TRUE,tbl_die_ordering[[#This Row],[Supplier]],tbl_die_ordering[[#This Row],[DIE NO]]) -> PDTMC_051137-2501
